<?xml version="1.0"?>
<robot xmlns:xacro="http://www.ros.org/wiki/xacro" >


<xacro:macro name="wheel" params="name xyz rpy parent color radius length mass">
  
    <joint name="${name}_wheel_joint" type="continuous">
        <parent link="${parent}"/>
        <child link="${name}_wheel"/>
        <origin xyz="${xyz}" rpy="${rpy}" />
        <axis xyz="0 0 1"/>
    </joint>

    <link name="${name}_wheel">
        <visual>
            <geometry>
                <cylinder radius="${radius}" length="${length}"/>
            </geometry>
            <material name="${color}"/>
        </visual>
        <collision>
            <geometry>
                <cylinder radius="${radius}" length="${length}"/>
            </geometry>
        </collision>
        <xacro:inertial_cylinder mass="${mass}" length="${length}" radius="${radius}">
            <origin xyz="0 0 0" rpy="0 0 0"/>
        </xacro:inertial_cylinder>
    </link>


</xacro:macro>

    
</robot>