<?xml version="1.0" ?>
<!-- =================================================================================== -->
<!-- |    This document was autogenerated by xacro from triskarino.urdf.xacro          | -->
<!-- |    EDITING THIS FILE BY HAND IS NOT RECOMMENDED                                 | -->
<!-- =================================================================================== -->
<robot name="triskarino">
  <!-- Specify some standard inertial calculations https://en.wikipedia.org/wiki/List_of_moments_of_inertia -->
  <!-- These make use of xacro's mathematical functionality -->
  <!-- Specify some standard inertial calculations https://en.wikipedia.org/wiki/List_of_moments_of_inertia -->
  <!-- These make use of xacro's mathematical functionality -->
  <material name="black">
    <color rgba="0.0 0.0 0.0 1.0"/>
  </material>
  <material name="blue">
    <color rgba="0.0 0.0 0.8 1.0"/>
  </material>
  <material name="green">
    <color rgba="0.0 0.8 0.0 1.0"/>
  </material>
  <material name="grey">
    <color rgba="0.2 0.2 0.2 1.0"/>
  </material>
  <material name="orange">
    <color rgba="1.0 0.4235294117647059 0.0392156862745098 1.0"/>
  </material>
  <material name="dark_grey">
    <color rgba="0.8627450980392157 0.8627450980392157 0.8627450980392157 1.0"/>
  </material>
  <material name="brown">
    <color rgba="0.8705882352941177 0.8117647058823529 0.7647058823529411 1.0"/>
  </material>
  <material name="red">
    <color rgba="0.8 0.0 0.0 1.0"/>
  </material>
  <material name="white">
    <color rgba="1.0 1.0 1.0 1.0"/>
  </material>
  <link name="base_link"/>
  <link name="plate_link">
    <inertial>
      <origin xyz="0.00000000 0.00000000 33.57142844"/>
      <mass value="1.00000000"/>
      <inertia ixx="6092.55688578" ixy="-0.00000000" ixz="0.00000000" iyy="6092.55696749" iyz="0.00000265" izz="11631.80010839"/>
    </inertial>
    <visual>
      <geometry>
        <mesh filename="package://triskarino_description/meshes/robot_base.stl" scale="0.001 0.001 0.001"/>
      </geometry>
      <material name="base_material">
        <color rgba="1 1 1 1"/>
      </material>
      <origin rpy="0 3.14 0"/>
    </visual>
    <collision>
      <geometry>
        <mesh filename="package://triskarino_description/meshes/robot_base.stl" scale="0.001 0.001 0.001"/>
      </geometry>
      <origin rpy="0 3.14 0"/>
    </collision>
  </link>
  <joint name="plate_joint" type="fixed">
    <parent link="base_link"/>
    <child link="plate_link"/>
    <origin rpy="0 0 0" xyz="0 0 0.1"/>
  </joint>
  <gazebo reference="plate_link">
    <mu1 value="0.0"/>
    <mu2 value="0.0"/>
    <kp value="1000000"/>
    <kd value="1"/>
    <implicitSpringDamper>true</implicitSpringDamper>
    <implicitSpringDamper>true</implicitSpringDamper>
    <maxContacts value="0"/>
  </gazebo>
  <joint name="base_footprint_joint" type="fixed">
    <parent link="base_link"/>
    <child link="base_footprint"/>
    <origin rpy="0 0 0" xyz="0 0 0"/>
  </joint>
  <link name="base_footprint"/>
  <joint name="rim_left_joint" type="continuous">
    <parent link="plate_link"/>
    <child link="rim_left_link"/>
    <axis xyz="0 0 1"/>
    <origin rpy="1.570796326794896 0 1.047197551196597" xyz="-0.142894191624 0.0825 -0.035"/>
  </joint>
  <link name="rim_left_link">
    <inertial>
      <origin xyz="-0.00000435 -0.00000262 -0.00011790"/>
      <mass value="0.20000000"/>
      <inertia ixx="0.00005620" ixy="-0.00000000" ixz="0.00000000" iyy="0.00005620" iyz="-0.00000000" izz="0.00007735"/>
    </inertial>
    <visual>
      <geometry>
        <mesh filename="package://triskarino_description/meshes/rim_scaled.stl"/>
      </geometry>
      <material name="rim_left_material">
        <color rgba="0.3 0 0 1"/>
      </material>
    </visual>
    <collision>
      <origin rpy="0 0 0" xyz="0 0 0"/>
      <geometry>
        <cylinder length="0.02" radius="0.032"/>
      </geometry>
      <surface>
        <bounce restitution_coefficient="0.0001"/>
      </surface>
    </collision>
  </link>
  <link name="roller_e_rim_left_link_link">
    <inertial>
      <origin xyz="0.00000004 -0.00000000 -0.00000002"/>
      <mass value="0.05000000"/>
      <inertia ixx="0.00000328" ixy="0.00000000" ixz="-0.00000000" iyy="0.00000328" iyz="-0.00000000" izz="0.00000191"/>
    </inertial>
    <visual>
      <geometry>
        <mesh filename="package://triskarino_description/meshes/roller_scaled.stl"/>
      </geometry>
      <material name="roller_material">
        <color rgba="0.1 0.1 0.1 1"/>
      </material>
    </visual>
    <collision>
      <geometry>
        <mesh filename="package://triskarino_description/meshes/roller_scaled.stl"/>
      </geometry>
    </collision>
  </link>
  <gazebo reference="roller_e_{parent}">
    <material>Gazebo/Black</material>
  </gazebo>
  <joint name="roller_e_rim_left_link_joint" type="continuous">
    <parent link="rim_left_link"/>
    <child link="roller_e_rim_left_link_link"/>
    <axis xyz="0 0 1"/>
    <origin rpy="-1.570796326794896 0 0" xyz="0.01355 0 0.0055"/>
  </joint>
  <gazebo reference="roller_e_rim_left_link_link">
    <mu1 value="0.0"/>
    <mu2 value="0.0"/>
    <minDepth>0.001</minDepth>
    <kp value="1000000"/>
    <kd value="1"/>
    <maxContacts value="0"/>
  </gazebo>
  <link name="roller_ne_rim_left_link_link">
    <inertial>
      <origin xyz="0.00000004 -0.00000000 -0.00000002"/>
      <mass value="0.05000000"/>
      <inertia ixx="0.00000328" ixy="0.00000000" ixz="-0.00000000" iyy="0.00000328" iyz="-0.00000000" izz="0.00000191"/>
    </inertial>
    <visual>
      <geometry>
        <mesh filename="package://triskarino_description/meshes/roller_scaled.stl"/>
      </geometry>
      <material name="roller_material">
        <color rgba="0.1 0.1 0.1 1"/>
      </material>
    </visual>
    <collision>
      <geometry>
        <mesh filename="package://triskarino_description/meshes/roller_scaled.stl"/>
      </geometry>
    </collision>
  </link>
  <gazebo reference="roller_ne_{parent}">
    <material>Gazebo/Black</material>
  </gazebo>
  <joint name="roller_ne_rim_left_link_joint" type="continuous">
    <parent link="rim_left_link"/>
    <child link="roller_ne_rim_left_link_link"/>
    <axis xyz="0 0 1"/>
    <origin rpy="-1.570796326794896 0 0.7853981633974483" xyz="0.00958129689 0.00958129689 -0.0055"/>
  </joint>
  <gazebo reference="roller_ne_rim_left_link_link">
    <mu1 value="0.0"/>
    <mu2 value="0.0"/>
    <minDepth>0.001</minDepth>
    <kp value="1000000"/>
    <kd value="1"/>
    <maxContacts value="0"/>
  </gazebo>
  <link name="roller_n_rim_left_link_link">
    <inertial>
      <origin xyz="0.00000004 -0.00000000 -0.00000002"/>
      <mass value="0.05000000"/>
      <inertia ixx="0.00000328" ixy="0.00000000" ixz="-0.00000000" iyy="0.00000328" iyz="-0.00000000" izz="0.00000191"/>
    </inertial>
    <visual>
      <geometry>
        <mesh filename="package://triskarino_description/meshes/roller_scaled.stl"/>
      </geometry>
      <material name="roller_material">
        <color rgba="0.1 0.1 0.1 1"/>
      </material>
    </visual>
    <collision>
      <geometry>
        <mesh filename="package://triskarino_description/meshes/roller_scaled.stl"/>
      </geometry>
    </collision>
  </link>
  <gazebo reference="roller_n_{parent}">
    <material>Gazebo/Black</material>
  </gazebo>
  <joint name="roller_n_rim_left_link_joint" type="continuous">
    <parent link="rim_left_link"/>
    <child link="roller_n_rim_left_link_link"/>
    <axis xyz="0 0 1"/>
    <origin rpy="-1.570796326794896 0 1.570796326794896" xyz="0 0.01355 0.0055"/>
  </joint>
  <gazebo reference="roller_n_rim_left_link_link">
    <mu1 value="0.0"/>
    <mu2 value="0.0"/>
    <minDepth>0.001</minDepth>
    <kp value="1000000"/>
    <kd value="1"/>
    <maxContacts value="0"/>
  </gazebo>
  <link name="roller_nw_rim_left_link_link">
    <inertial>
      <origin xyz="0.00000004 -0.00000000 -0.00000002"/>
      <mass value="0.05000000"/>
      <inertia ixx="0.00000328" ixy="0.00000000" ixz="-0.00000000" iyy="0.00000328" iyz="-0.00000000" izz="0.00000191"/>
    </inertial>
    <visual>
      <geometry>
        <mesh filename="package://triskarino_description/meshes/roller_scaled.stl"/>
      </geometry>
      <material name="roller_material">
        <color rgba="0.1 0.1 0.1 1"/>
      </material>
    </visual>
    <collision>
      <geometry>
        <mesh filename="package://triskarino_description/meshes/roller_scaled.stl"/>
      </geometry>
    </collision>
  </link>
  <gazebo reference="roller_nw_{parent}">
    <material>Gazebo/Black</material>
  </gazebo>
  <joint name="roller_nw_rim_left_link_joint" type="continuous">
    <parent link="rim_left_link"/>
    <child link="roller_nw_rim_left_link_link"/>
    <axis xyz="0 0 1"/>
    <origin rpy="-1.570796326794896 0 2.356194490192345" xyz="-0.00958129689 0.00958129689 -0.0055"/>
  </joint>
  <gazebo reference="roller_nw_rim_left_link_link">
    <mu1 value="0.0"/>
    <mu2 value="0.0"/>
    <minDepth>0.001</minDepth>
    <kp value="1000000"/>
    <kd value="1"/>
    <maxContacts value="0"/>
  </gazebo>
  <link name="roller_w_rim_left_link_link">
    <inertial>
      <origin xyz="0.00000004 -0.00000000 -0.00000002"/>
      <mass value="0.05000000"/>
      <inertia ixx="0.00000328" ixy="0.00000000" ixz="-0.00000000" iyy="0.00000328" iyz="-0.00000000" izz="0.00000191"/>
    </inertial>
    <visual>
      <geometry>
        <mesh filename="package://triskarino_description/meshes/roller_scaled.stl"/>
      </geometry>
      <material name="roller_material">
        <color rgba="0.1 0.1 0.1 1"/>
      </material>
    </visual>
    <collision>
      <geometry>
        <mesh filename="package://triskarino_description/meshes/roller_scaled.stl"/>
      </geometry>
    </collision>
  </link>
  <gazebo reference="roller_w_{parent}">
    <material>Gazebo/Black</material>
  </gazebo>
  <joint name="roller_w_rim_left_link_joint" type="continuous">
    <parent link="rim_left_link"/>
    <child link="roller_w_rim_left_link_link"/>
    <axis xyz="0 0 1"/>
    <origin rpy="-1.570796326794896 0 3.141592653589793" xyz="-0.01355 0 0.0055"/>
  </joint>
  <gazebo reference="roller_w_rim_left_link_link">
    <mu1 value="0.0"/>
    <mu2 value="0.0"/>
    <minDepth>0.001</minDepth>
    <kp value="1000000"/>
    <kd value="1"/>
    <maxContacts value="0"/>
  </gazebo>
  <link name="roller_sw_rim_left_link_link">
    <inertial>
      <origin xyz="0.00000004 -0.00000000 -0.00000002"/>
      <mass value="0.05000000"/>
      <inertia ixx="0.00000328" ixy="0.00000000" ixz="-0.00000000" iyy="0.00000328" iyz="-0.00000000" izz="0.00000191"/>
    </inertial>
    <visual>
      <geometry>
        <mesh filename="package://triskarino_description/meshes/roller_scaled.stl"/>
      </geometry>
      <material name="roller_material">
        <color rgba="0.1 0.1 0.1 1"/>
      </material>
    </visual>
    <collision>
      <geometry>
        <mesh filename="package://triskarino_description/meshes/roller_scaled.stl"/>
      </geometry>
    </collision>
  </link>
  <gazebo reference="roller_sw_{parent}">
    <material>Gazebo/Black</material>
  </gazebo>
  <joint name="roller_sw_rim_left_link_joint" type="continuous">
    <parent link="rim_left_link"/>
    <child link="roller_sw_rim_left_link_link"/>
    <axis xyz="0 0 1"/>
    <origin rpy="-1.570796326794896 0 -2.356194490192345" xyz="-0.00958129689 -0.00958129689 -0.0055"/>
  </joint>
  <gazebo reference="roller_sw_rim_left_link_link">
    <mu1 value="0.0"/>
    <mu2 value="0.0"/>
    <minDepth>0.001</minDepth>
    <kp value="1000000"/>
    <kd value="1"/>
    <maxContacts value="0"/>
  </gazebo>
  <link name="roller_s_rim_left_link_link">
    <inertial>
      <origin xyz="0.00000004 -0.00000000 -0.00000002"/>
      <mass value="0.05000000"/>
      <inertia ixx="0.00000328" ixy="0.00000000" ixz="-0.00000000" iyy="0.00000328" iyz="-0.00000000" izz="0.00000191"/>
    </inertial>
    <visual>
      <geometry>
        <mesh filename="package://triskarino_description/meshes/roller_scaled.stl"/>
      </geometry>
      <material name="roller_material">
        <color rgba="0.1 0.1 0.1 1"/>
      </material>
    </visual>
    <collision>
      <geometry>
        <mesh filename="package://triskarino_description/meshes/roller_scaled.stl"/>
      </geometry>
    </collision>
  </link>
  <gazebo reference="roller_s_{parent}">
    <material>Gazebo/Black</material>
  </gazebo>
  <joint name="roller_s_rim_left_link_joint" type="continuous">
    <parent link="rim_left_link"/>
    <child link="roller_s_rim_left_link_link"/>
    <axis xyz="0 0 1"/>
    <origin rpy="-1.570796326794896 0 -1.570796326794896" xyz="0 -0.01355 0.0055"/>
  </joint>
  <gazebo reference="roller_s_rim_left_link_link">
    <mu1 value="0.0"/>
    <mu2 value="0.0"/>
    <minDepth>0.001</minDepth>
    <kp value="1000000"/>
    <kd value="1"/>
    <maxContacts value="0"/>
  </gazebo>
  <link name="roller_se_rim_left_link_link">
    <inertial>
      <origin xyz="0.00000004 -0.00000000 -0.00000002"/>
      <mass value="0.05000000"/>
      <inertia ixx="0.00000328" ixy="0.00000000" ixz="-0.00000000" iyy="0.00000328" iyz="-0.00000000" izz="0.00000191"/>
    </inertial>
    <visual>
      <geometry>
        <mesh filename="package://triskarino_description/meshes/roller_scaled.stl"/>
      </geometry>
      <material name="roller_material">
        <color rgba="0.1 0.1 0.1 1"/>
      </material>
    </visual>
    <collision>
      <geometry>
        <mesh filename="package://triskarino_description/meshes/roller_scaled.stl"/>
      </geometry>
    </collision>
  </link>
  <gazebo reference="roller_se_{parent}">
    <material>Gazebo/Black</material>
  </gazebo>
  <joint name="roller_se_rim_left_link_joint" type="continuous">
    <parent link="rim_left_link"/>
    <child link="roller_se_rim_left_link_link"/>
    <axis xyz="0 0 1"/>
    <origin rpy="-1.570796326794896 0 -0.7853981633974483" xyz="0.00958129689 -0.00958129689 -0.0055"/>
  </joint>
  <gazebo reference="roller_se_rim_left_link_link">
    <mu1 value="0.0"/>
    <mu2 value="0.0"/>
    <minDepth>0.001</minDepth>
    <kp value="1000000"/>
    <kd value="1"/>
    <maxContacts value="0"/>
  </gazebo>
  <transmission name="rim_left_transmission">
    <type>transmission_interface/SimpleTransmission</type>
    <joint name="rim_left_joint">
      <hardwareInterface>hardware_interface/VelocityJointInterface</hardwareInterface>
    </joint>
    <actuator name="rim_left_motor">
      <hardwareInterface>hardware_interface/VelocityJointInterface</hardwareInterface>
      <mechanicalReduction>1</mechanicalReduction>
    </actuator>
  </transmission>
  <gazebo reference="rim_left_link">
    <collision name="rim_left_link_collision">
      <surface>
        <contact>
          <ode>
            <kp>1e+6</kp>
            <kd>1</kd>
            <min_depth>0.00001</min_depth>
          </ode>
        </contact>
        <friction>
          <ode>
            <mu>0</mu>
            <mu2>0</mu2>
            <max_contacts>2</max_contacts>
            <fdir1>0 0 1</fdir1>
            <slip1>1</slip1>
            <slip2>1</slip2>
          </ode>
        </friction>
      </surface>
    </collision>
  </gazebo>
  <joint name="rim_back_joint" type="continuous">
    <parent link="plate_link"/>
    <child link="rim_back_link"/>
    <axis xyz="0 0 1"/>
    <origin rpy="1.570796326794896 0 3.141592653589793" xyz="0 -0.1650 -0.035"/>
  </joint>
  <link name="rim_back_link">
    <inertial>
      <origin xyz="-0.00000435 -0.00000262 -0.00011790"/>
      <mass value="0.20000000"/>
      <inertia ixx="0.00005620" ixy="-0.00000000" ixz="0.00000000" iyy="0.00005620" iyz="-0.00000000" izz="0.00007735"/>
    </inertial>
    <visual>
      <geometry>
        <mesh filename="package://triskarino_description/meshes/rim_scaled.stl"/>
      </geometry>
      <material name="rim_back_material">
        <color rgba="0 0.3 0 1"/>
      </material>
    </visual>
    <collision>
      <origin rpy="0 0 0" xyz="0 0 0"/>
      <geometry>
        <cylinder length="0.02" radius="0.032"/>
      </geometry>
      <surface>
        <bounce restitution_coefficient="0.0001"/>
      </surface>
    </collision>
  </link>
  <link name="roller_e_rim_back_link_link">
    <inertial>
      <origin xyz="0.00000004 -0.00000000 -0.00000002"/>
      <mass value="0.05000000"/>
      <inertia ixx="0.00000328" ixy="0.00000000" ixz="-0.00000000" iyy="0.00000328" iyz="-0.00000000" izz="0.00000191"/>
    </inertial>
    <visual>
      <geometry>
        <mesh filename="package://triskarino_description/meshes/roller_scaled.stl"/>
      </geometry>
      <material name="roller_material">
        <color rgba="0.1 0.1 0.1 1"/>
      </material>
    </visual>
    <collision>
      <geometry>
        <mesh filename="package://triskarino_description/meshes/roller_scaled.stl"/>
      </geometry>
    </collision>
  </link>
  <gazebo reference="roller_e_{parent}">
    <material>Gazebo/Black</material>
  </gazebo>
  <joint name="roller_e_rim_back_link_joint" type="continuous">
    <parent link="rim_back_link"/>
    <child link="roller_e_rim_back_link_link"/>
    <axis xyz="0 0 1"/>
    <origin rpy="-1.570796326794896 0 0" xyz="0.01355 0 0.0055"/>
  </joint>
  <gazebo reference="roller_e_rim_back_link_link">
    <mu1 value="0.0"/>
    <mu2 value="0.0"/>
    <minDepth>0.001</minDepth>
    <kp value="1000000"/>
    <kd value="1"/>
    <maxContacts value="0"/>
  </gazebo>
  <link name="roller_ne_rim_back_link_link">
    <inertial>
      <origin xyz="0.00000004 -0.00000000 -0.00000002"/>
      <mass value="0.05000000"/>
      <inertia ixx="0.00000328" ixy="0.00000000" ixz="-0.00000000" iyy="0.00000328" iyz="-0.00000000" izz="0.00000191"/>
    </inertial>
    <visual>
      <geometry>
        <mesh filename="package://triskarino_description/meshes/roller_scaled.stl"/>
      </geometry>
      <material name="roller_material">
        <color rgba="0.1 0.1 0.1 1"/>
      </material>
    </visual>
    <collision>
      <geometry>
        <mesh filename="package://triskarino_description/meshes/roller_scaled.stl"/>
      </geometry>
    </collision>
  </link>
  <gazebo reference="roller_ne_{parent}">
    <material>Gazebo/Black</material>
  </gazebo>
  <joint name="roller_ne_rim_back_link_joint" type="continuous">
    <parent link="rim_back_link"/>
    <child link="roller_ne_rim_back_link_link"/>
    <axis xyz="0 0 1"/>
    <origin rpy="-1.570796326794896 0 0.7853981633974483" xyz="0.00958129689 0.00958129689 -0.0055"/>
  </joint>
  <gazebo reference="roller_ne_rim_back_link_link">
    <mu1 value="0.0"/>
    <mu2 value="0.0"/>
    <minDepth>0.001</minDepth>
    <kp value="1000000"/>
    <kd value="1"/>
    <maxContacts value="0"/>
  </gazebo>
  <link name="roller_n_rim_back_link_link">
    <inertial>
      <origin xyz="0.00000004 -0.00000000 -0.00000002"/>
      <mass value="0.05000000"/>
      <inertia ixx="0.00000328" ixy="0.00000000" ixz="-0.00000000" iyy="0.00000328" iyz="-0.00000000" izz="0.00000191"/>
    </inertial>
    <visual>
      <geometry>
        <mesh filename="package://triskarino_description/meshes/roller_scaled.stl"/>
      </geometry>
      <material name="roller_material">
        <color rgba="0.1 0.1 0.1 1"/>
      </material>
    </visual>
    <collision>
      <geometry>
        <mesh filename="package://triskarino_description/meshes/roller_scaled.stl"/>
      </geometry>
    </collision>
  </link>
  <gazebo reference="roller_n_{parent}">
    <material>Gazebo/Black</material>
  </gazebo>
  <joint name="roller_n_rim_back_link_joint" type="continuous">
    <parent link="rim_back_link"/>
    <child link="roller_n_rim_back_link_link"/>
    <axis xyz="0 0 1"/>
    <origin rpy="-1.570796326794896 0 1.570796326794896" xyz="0 0.01355 0.0055"/>
  </joint>
  <gazebo reference="roller_n_rim_back_link_link">
    <mu1 value="0.0"/>
    <mu2 value="0.0"/>
    <minDepth>0.001</minDepth>
    <kp value="1000000"/>
    <kd value="1"/>
    <maxContacts value="0"/>
  </gazebo>
  <link name="roller_nw_rim_back_link_link">
    <inertial>
      <origin xyz="0.00000004 -0.00000000 -0.00000002"/>
      <mass value="0.05000000"/>
      <inertia ixx="0.00000328" ixy="0.00000000" ixz="-0.00000000" iyy="0.00000328" iyz="-0.00000000" izz="0.00000191"/>
    </inertial>
    <visual>
      <geometry>
        <mesh filename="package://triskarino_description/meshes/roller_scaled.stl"/>
      </geometry>
      <material name="roller_material">
        <color rgba="0.1 0.1 0.1 1"/>
      </material>
    </visual>
    <collision>
      <geometry>
        <mesh filename="package://triskarino_description/meshes/roller_scaled.stl"/>
      </geometry>
    </collision>
  </link>
  <gazebo reference="roller_nw_{parent}">
    <material>Gazebo/Black</material>
  </gazebo>
  <joint name="roller_nw_rim_back_link_joint" type="continuous">
    <parent link="rim_back_link"/>
    <child link="roller_nw_rim_back_link_link"/>
    <axis xyz="0 0 1"/>
    <origin rpy="-1.570796326794896 0 2.356194490192345" xyz="-0.00958129689 0.00958129689 -0.0055"/>
  </joint>
  <gazebo reference="roller_nw_rim_back_link_link">
    <mu1 value="0.0"/>
    <mu2 value="0.0"/>
    <minDepth>0.001</minDepth>
    <kp value="1000000"/>
    <kd value="1"/>
    <maxContacts value="0"/>
  </gazebo>
  <link name="roller_w_rim_back_link_link">
    <inertial>
      <origin xyz="0.00000004 -0.00000000 -0.00000002"/>
      <mass value="0.05000000"/>
      <inertia ixx="0.00000328" ixy="0.00000000" ixz="-0.00000000" iyy="0.00000328" iyz="-0.00000000" izz="0.00000191"/>
    </inertial>
    <visual>
      <geometry>
        <mesh filename="package://triskarino_description/meshes/roller_scaled.stl"/>
      </geometry>
      <material name="roller_material">
        <color rgba="0.1 0.1 0.1 1"/>
      </material>
    </visual>
    <collision>
      <geometry>
        <mesh filename="package://triskarino_description/meshes/roller_scaled.stl"/>
      </geometry>
    </collision>
  </link>
  <gazebo reference="roller_w_{parent}">
    <material>Gazebo/Black</material>
  </gazebo>
  <joint name="roller_w_rim_back_link_joint" type="continuous">
    <parent link="rim_back_link"/>
    <child link="roller_w_rim_back_link_link"/>
    <axis xyz="0 0 1"/>
    <origin rpy="-1.570796326794896 0 3.141592653589793" xyz="-0.01355 0 0.0055"/>
  </joint>
  <gazebo reference="roller_w_rim_back_link_link">
    <mu1 value="0.0"/>
    <mu2 value="0.0"/>
    <minDepth>0.001</minDepth>
    <kp value="1000000"/>
    <kd value="1"/>
    <maxContacts value="0"/>
  </gazebo>
  <link name="roller_sw_rim_back_link_link">
    <inertial>
      <origin xyz="0.00000004 -0.00000000 -0.00000002"/>
      <mass value="0.05000000"/>
      <inertia ixx="0.00000328" ixy="0.00000000" ixz="-0.00000000" iyy="0.00000328" iyz="-0.00000000" izz="0.00000191"/>
    </inertial>
    <visual>
      <geometry>
        <mesh filename="package://triskarino_description/meshes/roller_scaled.stl"/>
      </geometry>
      <material name="roller_material">
        <color rgba="0.1 0.1 0.1 1"/>
      </material>
    </visual>
    <collision>
      <geometry>
        <mesh filename="package://triskarino_description/meshes/roller_scaled.stl"/>
      </geometry>
    </collision>
  </link>
  <gazebo reference="roller_sw_{parent}">
    <material>Gazebo/Black</material>
  </gazebo>
  <joint name="roller_sw_rim_back_link_joint" type="continuous">
    <parent link="rim_back_link"/>
    <child link="roller_sw_rim_back_link_link"/>
    <axis xyz="0 0 1"/>
    <origin rpy="-1.570796326794896 0 -2.356194490192345" xyz="-0.00958129689 -0.00958129689 -0.0055"/>
  </joint>
  <gazebo reference="roller_sw_rim_back_link_link">
    <mu1 value="0.0"/>
    <mu2 value="0.0"/>
    <minDepth>0.001</minDepth>
    <kp value="1000000"/>
    <kd value="1"/>
    <maxContacts value="0"/>
  </gazebo>
  <link name="roller_s_rim_back_link_link">
    <inertial>
      <origin xyz="0.00000004 -0.00000000 -0.00000002"/>
      <mass value="0.05000000"/>
      <inertia ixx="0.00000328" ixy="0.00000000" ixz="-0.00000000" iyy="0.00000328" iyz="-0.00000000" izz="0.00000191"/>
    </inertial>
    <visual>
      <geometry>
        <mesh filename="package://triskarino_description/meshes/roller_scaled.stl"/>
      </geometry>
      <material name="roller_material">
        <color rgba="0.1 0.1 0.1 1"/>
      </material>
    </visual>
    <collision>
      <geometry>
        <mesh filename="package://triskarino_description/meshes/roller_scaled.stl"/>
      </geometry>
    </collision>
  </link>
  <gazebo reference="roller_s_{parent}">
    <material>Gazebo/Black</material>
  </gazebo>
  <joint name="roller_s_rim_back_link_joint" type="continuous">
    <parent link="rim_back_link"/>
    <child link="roller_s_rim_back_link_link"/>
    <axis xyz="0 0 1"/>
    <origin rpy="-1.570796326794896 0 -1.570796326794896" xyz="0 -0.01355 0.0055"/>
  </joint>
  <gazebo reference="roller_s_rim_back_link_link">
    <mu1 value="0.0"/>
    <mu2 value="0.0"/>
    <minDepth>0.001</minDepth>
    <kp value="1000000"/>
    <kd value="1"/>
    <maxContacts value="0"/>
  </gazebo>
  <link name="roller_se_rim_back_link_link">
    <inertial>
      <origin xyz="0.00000004 -0.00000000 -0.00000002"/>
      <mass value="0.05000000"/>
      <inertia ixx="0.00000328" ixy="0.00000000" ixz="-0.00000000" iyy="0.00000328" iyz="-0.00000000" izz="0.00000191"/>
    </inertial>
    <visual>
      <geometry>
        <mesh filename="package://triskarino_description/meshes/roller_scaled.stl"/>
      </geometry>
      <material name="roller_material">
        <color rgba="0.1 0.1 0.1 1"/>
      </material>
    </visual>
    <collision>
      <geometry>
        <mesh filename="package://triskarino_description/meshes/roller_scaled.stl"/>
      </geometry>
    </collision>
  </link>
  <gazebo reference="roller_se_{parent}">
    <material>Gazebo/Black</material>
  </gazebo>
  <joint name="roller_se_rim_back_link_joint" type="continuous">
    <parent link="rim_back_link"/>
    <child link="roller_se_rim_back_link_link"/>
    <axis xyz="0 0 1"/>
    <origin rpy="-1.570796326794896 0 -0.7853981633974483" xyz="0.00958129689 -0.00958129689 -0.0055"/>
  </joint>
  <gazebo reference="roller_se_rim_back_link_link">
    <mu1 value="0.0"/>
    <mu2 value="0.0"/>
    <minDepth>0.001</minDepth>
    <kp value="1000000"/>
    <kd value="1"/>
    <maxContacts value="0"/>
  </gazebo>
  <transmission name="rim_back_transmission">
    <type>transmission_interface/SimpleTransmission</type>
    <joint name="rim_back_joint">
      <hardwareInterface>hardware_interface/VelocityJointInterface</hardwareInterface>
    </joint>
    <actuator name="rim_back_motor">
      <hardwareInterface>hardware_interface/VelocityJointInterface</hardwareInterface>
      <mechanicalReduction>1</mechanicalReduction>
    </actuator>
  </transmission>
  <gazebo reference="rim_back_link">
    <collision name="rim_back_link_collision">
      <surface>
        <contact>
          <ode>
            <kp>1e+6</kp>
            <kd>1</kd>
            <min_depth>0.00001</min_depth>
          </ode>
        </contact>
        <friction>
          <ode>
            <mu>0</mu>
            <mu2>0</mu2>
            <max_contacts>2</max_contacts>
            <fdir1>0 0 1</fdir1>
            <slip1>1</slip1>
            <slip2>1</slip2>
          </ode>
        </friction>
      </surface>
    </collision>
  </gazebo>
  <joint name="rim_right_joint" type="continuous">
    <parent link="plate_link"/>
    <child link="rim_right_link"/>
    <axis xyz="0 0 1"/>
    <origin rpy="1.570796326794896 0 -1.047197551196597" xyz="0.142894191624 0.0825 -0.035"/>
  </joint>
  <link name="rim_right_link">
    <inertial>
      <origin xyz="-0.00000435 -0.00000262 -0.00011790"/>
      <mass value="0.20000000"/>
      <inertia ixx="0.00005620" ixy="-0.00000000" ixz="0.00000000" iyy="0.00005620" iyz="-0.00000000" izz="0.00007735"/>
    </inertial>
    <visual>
      <geometry>
        <mesh filename="package://triskarino_description/meshes/rim_scaled.stl"/>
      </geometry>
      <material name="rim_right_material">
        <color rgba="0 0 0.3 1"/>
      </material>
    </visual>
    <collision>
      <origin rpy="0 0 0" xyz="0 0 0"/>
      <geometry>
        <cylinder length="0.02" radius="0.032"/>
      </geometry>
      <surface>
        <bounce restitution_coefficient="0.0001"/>
      </surface>
    </collision>
  </link>
  <link name="roller_e_rim_right_link_link">
    <inertial>
      <origin xyz="0.00000004 -0.00000000 -0.00000002"/>
      <mass value="0.05000000"/>
      <inertia ixx="0.00000328" ixy="0.00000000" ixz="-0.00000000" iyy="0.00000328" iyz="-0.00000000" izz="0.00000191"/>
    </inertial>
    <visual>
      <geometry>
        <mesh filename="package://triskarino_description/meshes/roller_scaled.stl"/>
      </geometry>
      <material name="roller_material">
        <color rgba="0.1 0.1 0.1 1"/>
      </material>
    </visual>
    <collision>
      <geometry>
        <mesh filename="package://triskarino_description/meshes/roller_scaled.stl"/>
      </geometry>
    </collision>
  </link>
  <gazebo reference="roller_e_{parent}">
    <material>Gazebo/Black</material>
  </gazebo>
  <joint name="roller_e_rim_right_link_joint" type="continuous">
    <parent link="rim_right_link"/>
    <child link="roller_e_rim_right_link_link"/>
    <axis xyz="0 0 1"/>
    <origin rpy="-1.570796326794896 0 0" xyz="0.01355 0 0.0055"/>
  </joint>
  <gazebo reference="roller_e_rim_right_link_link">
    <mu1 value="0.0"/>
    <mu2 value="0.0"/>
    <minDepth>0.001</minDepth>
    <kp value="1000000"/>
    <kd value="1"/>
    <maxContacts value="0"/>
  </gazebo>
  <link name="roller_ne_rim_right_link_link">
    <inertial>
      <origin xyz="0.00000004 -0.00000000 -0.00000002"/>
      <mass value="0.05000000"/>
      <inertia ixx="0.00000328" ixy="0.00000000" ixz="-0.00000000" iyy="0.00000328" iyz="-0.00000000" izz="0.00000191"/>
    </inertial>
    <visual>
      <geometry>
        <mesh filename="package://triskarino_description/meshes/roller_scaled.stl"/>
      </geometry>
      <material name="roller_material">
        <color rgba="0.1 0.1 0.1 1"/>
      </material>
    </visual>
    <collision>
      <geometry>
        <mesh filename="package://triskarino_description/meshes/roller_scaled.stl"/>
      </geometry>
    </collision>
  </link>
  <gazebo reference="roller_ne_{parent}">
    <material>Gazebo/Black</material>
  </gazebo>
  <joint name="roller_ne_rim_right_link_joint" type="continuous">
    <parent link="rim_right_link"/>
    <child link="roller_ne_rim_right_link_link"/>
    <axis xyz="0 0 1"/>
    <origin rpy="-1.570796326794896 0 0.7853981633974483" xyz="0.00958129689 0.00958129689 -0.0055"/>
  </joint>
  <gazebo reference="roller_ne_rim_right_link_link">
    <mu1 value="0.0"/>
    <mu2 value="0.0"/>
    <minDepth>0.001</minDepth>
    <kp value="1000000"/>
    <kd value="1"/>
    <maxContacts value="0"/>
  </gazebo>
  <link name="roller_n_rim_right_link_link">
    <inertial>
      <origin xyz="0.00000004 -0.00000000 -0.00000002"/>
      <mass value="0.05000000"/>
      <inertia ixx="0.00000328" ixy="0.00000000" ixz="-0.00000000" iyy="0.00000328" iyz="-0.00000000" izz="0.00000191"/>
    </inertial>
    <visual>
      <geometry>
        <mesh filename="package://triskarino_description/meshes/roller_scaled.stl"/>
      </geometry>
      <material name="roller_material">
        <color rgba="0.1 0.1 0.1 1"/>
      </material>
    </visual>
    <collision>
      <geometry>
        <mesh filename="package://triskarino_description/meshes/roller_scaled.stl"/>
      </geometry>
    </collision>
  </link>
  <gazebo reference="roller_n_{parent}">
    <material>Gazebo/Black</material>
  </gazebo>
  <joint name="roller_n_rim_right_link_joint" type="continuous">
    <parent link="rim_right_link"/>
    <child link="roller_n_rim_right_link_link"/>
    <axis xyz="0 0 1"/>
    <origin rpy="-1.570796326794896 0 1.570796326794896" xyz="0 0.01355 0.0055"/>
  </joint>
  <gazebo reference="roller_n_rim_right_link_link">
    <mu1 value="0.0"/>
    <mu2 value="0.0"/>
    <minDepth>0.001</minDepth>
    <kp value="1000000"/>
    <kd value="1"/>
    <maxContacts value="0"/>
  </gazebo>
  <link name="roller_nw_rim_right_link_link">
    <inertial>
      <origin xyz="0.00000004 -0.00000000 -0.00000002"/>
      <mass value="0.05000000"/>
      <inertia ixx="0.00000328" ixy="0.00000000" ixz="-0.00000000" iyy="0.00000328" iyz="-0.00000000" izz="0.00000191"/>
    </inertial>
    <visual>
      <geometry>
        <mesh filename="package://triskarino_description/meshes/roller_scaled.stl"/>
      </geometry>
      <material name="roller_material">
        <color rgba="0.1 0.1 0.1 1"/>
      </material>
    </visual>
    <collision>
      <geometry>
        <mesh filename="package://triskarino_description/meshes/roller_scaled.stl"/>
      </geometry>
    </collision>
  </link>
  <gazebo reference="roller_nw_{parent}">
    <material>Gazebo/Black</material>
  </gazebo>
  <joint name="roller_nw_rim_right_link_joint" type="continuous">
    <parent link="rim_right_link"/>
    <child link="roller_nw_rim_right_link_link"/>
    <axis xyz="0 0 1"/>
    <origin rpy="-1.570796326794896 0 2.356194490192345" xyz="-0.00958129689 0.00958129689 -0.0055"/>
  </joint>
  <gazebo reference="roller_nw_rim_right_link_link">
    <mu1 value="0.0"/>
    <mu2 value="0.0"/>
    <minDepth>0.001</minDepth>
    <kp value="1000000"/>
    <kd value="1"/>
    <maxContacts value="0"/>
  </gazebo>
  <link name="roller_w_rim_right_link_link">
    <inertial>
      <origin xyz="0.00000004 -0.00000000 -0.00000002"/>
      <mass value="0.05000000"/>
      <inertia ixx="0.00000328" ixy="0.00000000" ixz="-0.00000000" iyy="0.00000328" iyz="-0.00000000" izz="0.00000191"/>
    </inertial>
    <visual>
      <geometry>
        <mesh filename="package://triskarino_description/meshes/roller_scaled.stl"/>
      </geometry>
      <material name="roller_material">
        <color rgba="0.1 0.1 0.1 1"/>
      </material>
    </visual>
    <collision>
      <geometry>
        <mesh filename="package://triskarino_description/meshes/roller_scaled.stl"/>
      </geometry>
    </collision>
  </link>
  <gazebo reference="roller_w_{parent}">
    <material>Gazebo/Black</material>
  </gazebo>
  <joint name="roller_w_rim_right_link_joint" type="continuous">
    <parent link="rim_right_link"/>
    <child link="roller_w_rim_right_link_link"/>
    <axis xyz="0 0 1"/>
    <origin rpy="-1.570796326794896 0 3.141592653589793" xyz="-0.01355 0 0.0055"/>
  </joint>
  <gazebo reference="roller_w_rim_right_link_link">
    <mu1 value="0.0"/>
    <mu2 value="0.0"/>
    <minDepth>0.001</minDepth>
    <kp value="1000000"/>
    <kd value="1"/>
    <maxContacts value="0"/>
  </gazebo>
  <link name="roller_sw_rim_right_link_link">
    <inertial>
      <origin xyz="0.00000004 -0.00000000 -0.00000002"/>
      <mass value="0.05000000"/>
      <inertia ixx="0.00000328" ixy="0.00000000" ixz="-0.00000000" iyy="0.00000328" iyz="-0.00000000" izz="0.00000191"/>
    </inertial>
    <visual>
      <geometry>
        <mesh filename="package://triskarino_description/meshes/roller_scaled.stl"/>
      </geometry>
      <material name="roller_material">
        <color rgba="0.1 0.1 0.1 1"/>
      </material>
    </visual>
    <collision>
      <geometry>
        <mesh filename="package://triskarino_description/meshes/roller_scaled.stl"/>
      </geometry>
    </collision>
  </link>
  <gazebo reference="roller_sw_{parent}">
    <material>Gazebo/Black</material>
  </gazebo>
  <joint name="roller_sw_rim_right_link_joint" type="continuous">
    <parent link="rim_right_link"/>
    <child link="roller_sw_rim_right_link_link"/>
    <axis xyz="0 0 1"/>
    <origin rpy="-1.570796326794896 0 -2.356194490192345" xyz="-0.00958129689 -0.00958129689 -0.0055"/>
  </joint>
  <gazebo reference="roller_sw_rim_right_link_link">
    <mu1 value="0.0"/>
    <mu2 value="0.0"/>
    <minDepth>0.001</minDepth>
    <kp value="1000000"/>
    <kd value="1"/>
    <maxContacts value="0"/>
  </gazebo>
  <link name="roller_s_rim_right_link_link">
    <inertial>
      <origin xyz="0.00000004 -0.00000000 -0.00000002"/>
      <mass value="0.05000000"/>
      <inertia ixx="0.00000328" ixy="0.00000000" ixz="-0.00000000" iyy="0.00000328" iyz="-0.00000000" izz="0.00000191"/>
    </inertial>
    <visual>
      <geometry>
        <mesh filename="package://triskarino_description/meshes/roller_scaled.stl"/>
      </geometry>
      <material name="roller_material">
        <color rgba="0.1 0.1 0.1 1"/>
      </material>
    </visual>
    <collision>
      <geometry>
        <mesh filename="package://triskarino_description/meshes/roller_scaled.stl"/>
      </geometry>
    </collision>
  </link>
  <gazebo reference="roller_s_{parent}">
    <material>Gazebo/Black</material>
  </gazebo>
  <joint name="roller_s_rim_right_link_joint" type="continuous">
    <parent link="rim_right_link"/>
    <child link="roller_s_rim_right_link_link"/>
    <axis xyz="0 0 1"/>
    <origin rpy="-1.570796326794896 0 -1.570796326794896" xyz="0 -0.01355 0.0055"/>
  </joint>
  <gazebo reference="roller_s_rim_right_link_link">
    <mu1 value="0.0"/>
    <mu2 value="0.0"/>
    <minDepth>0.001</minDepth>
    <kp value="1000000"/>
    <kd value="1"/>
    <maxContacts value="0"/>
  </gazebo>
  <link name="roller_se_rim_right_link_link">
    <inertial>
      <origin xyz="0.00000004 -0.00000000 -0.00000002"/>
      <mass value="0.05000000"/>
      <inertia ixx="0.00000328" ixy="0.00000000" ixz="-0.00000000" iyy="0.00000328" iyz="-0.00000000" izz="0.00000191"/>
    </inertial>
    <visual>
      <geometry>
        <mesh filename="package://triskarino_description/meshes/roller_scaled.stl"/>
      </geometry>
      <material name="roller_material">
        <color rgba="0.1 0.1 0.1 1"/>
      </material>
    </visual>
    <collision>
      <geometry>
        <mesh filename="package://triskarino_description/meshes/roller_scaled.stl"/>
      </geometry>
    </collision>
  </link>
  <gazebo reference="roller_se_{parent}">
    <material>Gazebo/Black</material>
  </gazebo>
  <joint name="roller_se_rim_right_link_joint" type="continuous">
    <parent link="rim_right_link"/>
    <child link="roller_se_rim_right_link_link"/>
    <axis xyz="0 0 1"/>
    <origin rpy="-1.570796326794896 0 -0.7853981633974483" xyz="0.00958129689 -0.00958129689 -0.0055"/>
  </joint>
  <gazebo reference="roller_se_rim_right_link_link">
    <mu1 value="0.0"/>
    <mu2 value="0.0"/>
    <minDepth>0.001</minDepth>
    <kp value="1000000"/>
    <kd value="1"/>
    <maxContacts value="0"/>
  </gazebo>
  <transmission name="rim_right_transmission">
    <type>transmission_interface/SimpleTransmission</type>
    <joint name="rim_right_joint">
      <hardwareInterface>hardware_interface/VelocityJointInterface</hardwareInterface>
    </joint>
    <actuator name="rim_right_motor">
      <hardwareInterface>hardware_interface/VelocityJointInterface</hardwareInterface>
      <mechanicalReduction>1</mechanicalReduction>
    </actuator>
  </transmission>
  <gazebo reference="rim_right_link">
    <collision name="rim_right_link_collision">
      <surface>
        <contact>
          <ode>
            <kp>1e+6</kp>
            <kd>1</kd>
            <min_depth>0.00001</min_depth>
          </ode>
        </contact>
        <friction>
          <ode>
            <mu>0</mu>
            <mu2>0</mu2>
            <max_contacts>2</max_contacts>
            <fdir1>0 0 1</fdir1>
            <slip1>1</slip1>
            <slip2>1</slip2>
          </ode>
        </friction>
      </surface>
    </collision>
  </gazebo>
  <joint name="axis_joint" type="fixed">
    <parent link="plate_link"/>
    <child link="axis_link"/>
    <origin rpy="0 0 0" xyz="0 0 0.2"/>
  </joint>
  <link name="axis_link">
    <visual>
      <geometry>
        <cylinder length="0.4" radius="0.01"/>
      </geometry>
      <material name="grey"/>
    </visual>
    <collision>
      <geometry>
        <cylinder length="0.4" radius="0.01"/>
      </geometry>
    </collision>
    <inertial>
      <origin rpy="0 0 0" xyz="0 0 0"/>
      <mass value="1"/>
      <inertia ixx="0.013358333333333335" ixy="0.0" ixz="0.0" iyy="0.013358333333333335" iyz="0.0" izz="5e-05"/>
    </inertial>
  </link>
  <joint name="layer_0_joint" type="fixed">
    <parent link="axis_link"/>
    <child link="layer_0_link"/>
    <origin rpy="0 0 0" xyz="0 0 -0.17"/>
  </joint>
  <link name="layer_0_link">
    <visual>
      <geometry>
        <cylinder length="0.01" radius="0.2"/>
      </geometry>
      <material name="grey"/>
    </visual>
    <collision>
      <geometry>
        <cylinder length="0.01" radius="0.2"/>
      </geometry>
    </collision>
    <inertial>
      <origin rpy="0 0 0" xyz="0 0 0"/>
      <mass value="1"/>
      <inertia ixx="0.010008333333333334" ixy="0.0" ixz="0.0" iyy="0.010008333333333334" iyz="0.0" izz="0.020000000000000004"/>
    </inertial>
  </link>
  <link name="laser">
    <inertial>
      <mass value="1.1"/>
      <origin xyz="0 0 0"/>
      <inertia ixx="0.00307156543804" ixy="0.0" ixz="0.0" iyy="0.0031284904152700005" iyz="0.0" izz="0.00196432421427"/>
    </inertial>
  </link>
  <gazebo reference="laser">
    <turnGravityOff>true</turnGravityOff>
    <sensor name="laser" type="ray">
      <pose>0 0 0 0 0 0</pose>
      <visualize>true</visualize>
      <update_rate>10.0</update_rate>
      <ray>
        <scan>
          <horizontal>
            <samples>720</samples>
            <resolution>1</resolution>
            <min_angle>-2.0944</min_angle>
            <max_angle>2.0944</max_angle>
          </horizontal>
        </scan>
        <range>
          <min>0.01</min>
          <max>30</max>
          <resolution>0.01</resolution>
        </range>
        <noise>
          <type>gaussian</type>
          <mean>0.0</mean>
          <stddev>0.001</stddev>
        </noise>
      </ray>
      <plugin filename="libgazebo_ros_laser.so" name="laser_controller">
        <tf_prefix/>
        <frameName>laser</frameName>
        <topicName>scan</topicName>
        <robotNamespace>triskarino</robotNamespace>
      </plugin>
    </sensor>
  </gazebo>
  <joint name="laser_mount_joint" type="fixed">
    <origin rpy="0 0 1.5708" xyz="0 0.11 0"/>
    <parent link="layer_0_link"/>
    <child link="laser_mount"/>
  </joint>
  <link name="laser_mount">
    <visual>
      <origin rpy="0 0 0" xyz="0 0 0"/>
      <geometry>
        <!-- Origin of this mesh is the base of the bracket. -->
        <mesh filename="package://triskarino_description/meshes/hokuyo_ust10.stl"/>
      </geometry>
      <material name="dark_grey"/>
    </visual>
  </link>
  <joint name="laser_joint" type="fixed">
    <!-- This offset is from the base of the bracket to the LIDAR's focal point. -->
    <origin rpy="0 0 0" xyz="0 0 0.0474"/>
    <parent link="laser_mount"/>
    <child link="laser"/>
  </joint>
  <!-- Fix to make rviz laserscan work! -->
  <gazebo reference="laser_mount">
    <material>Gazebo/DarkGrey</material>
  </gazebo>
  <gazebo reference="plate_link">
    <material>Gazebo/White</material>
  </gazebo>
  <gazebo reference="base_link">
    <mu1 value="0.0"/>
    <mu2 value="0.0"/>
  </gazebo>
</robot>
